Workbook

Sheet Read Me
A1: Ram-a-thon 2026 results (Rambots, Team 2204)
A2: CCA Hayward, Sat Oct 17 2026. Built from the sales laptop's CSV export (Laptop 1, exported 1:51 PM).
A4: What's tracked | B4: Every clicker and copter sale rung up on the sales laptop: 69 sales, 10:01 AM to 1:20 PM.
A5: What's not tracked | B5: Plinko (bucket not counted), Balloon Battle (laptop not exported), the Prize Table, and the end-of-day blowout sale. Those numbers are estimates and live in blue input cells.
A6: Blue cells | B6: Inputs. Change them (a stock count, an estimate, a weight) and every formula updates.
A7: Leaderboard | B7: Designs ranked by sales rate, plus the most popular designs with each age and gender group.
A8: Design Ranking | B8: The math behind the leaderboard. Sales rate is the main rank because we made unequal amounts of each design. The blended rank (70% rate, 30% units) is there for reference; the weights are inputs.
A9: Sales rate | B9: Units sold divided by hours the design was on the table. A sale counts at most 3 of one design toward the rate, so the parent who bought 8 Dumplings doesn't skew it.
A10: Stock & Lost Sales | B10: For designs that sold out: rate x hours left after the sellout = units we could have sold with unlimited stock. Also ideal stock for next year.
A11: Event Totals | B11: Tracked vs estimated tickets per booth, Plinko inferred as gross minus everything else, goals, and $ after CCA's 10%.
A12: Themes / Pairings | B12: Which kinds of clickers sold, and which designs were bought together.
A13: Demographics | B13: Who items were for (age and gender tags). About a third of sales are untagged, and Adults are only 4 sales, so treat small groups as hints.
A14: Findings | B14: Conclusions, hypotheses, and things to change next year.
A15: Raw Data | B15: The 11 export columns that hold data. The battle, prize, and laptop columns were empty or constant; the full export is ramathon_sales_laptop1_2026-10-17.csv in the repo.
... A17: Version | B17: ramathon_2026_results_v1.0.xlsx, built 2026-10-17 by build_ramathon_2026_results_v1.0.py

Sheet Findings
A1: Findings
A2: Conclusions are backed by the tracked data. Hypotheses are guesses worth testing next year.
A4: Headline numbers
A5: - | B5: About 900 tickets gross (830 counted + about 70 given to helpers for food), about $810 after CCA's 10%. Goal was 1,300: we hit about 69%.
A6: - | B6: Tracked: 69 sales, 129 clickers and 5 copter kits, 482 tickets.
A7: - | B7: Plinko (inferred): about 310 to 350 tickets, so roughly 330 drops at 1 ticket each. That's about 3.3x its 100-ticket goal and the second-biggest booth.
A9: Best designs (by sales rate: units per hour on the table)
A10: - | B10: Rate rank: 1. Dumpling (7.1/hr), 2. Salmon nigiri (6.9/hr), 3. Creeper (5.6/hr), 4. Avocado (4.4/hr), 5. Egg tart (3.3/hr), 5. Chocolate bar (3.3/hr). Egg tart and Chocolate bar tie at 5.
A11: - | B11: Dumpling and Salmon nigiri were the real demand leaders: about 7 an hour each while on the table. They also happened to be the two designs we made the most of, which is why they lead on units too.
A12: - | B12: Creeper sold out first. All 10 were gone by 11:48 AM with no bulk buys, about 90 minutes before the last sale. Its rate (5.6/hr) says we needed about 19 to last the day (23 with a 20% buffer), not 10.
A13: - | B13: Spam musubi only made 6 and sold its last 2 at 1:20 PM. It sold out, but slowly (1.8/hr): it was right-sized, not a hidden hit.
A14: - | B14: Slowest: S'mores (0.9/hr) and LEGO brick (0.6/hr).
A15: - | B15: The blended rank (70% rate, 30% units) comes out in the same order, so the call doesn't depend on how you weigh it.
A17: What we ran short on
A18: - | B18: Creeper, Dumpling, and Avocado sold out before the end. At their own pace, unlimited stock would have sold about 16 more clickers, about 56 tickets at 3.53 tix each. Creeper alone is 9 of those.
A19: - | B19: That's a floor. Clicker pace fell from 43 units/hour to 19 after 12:43 PM, once all three were gone. The crowd was thinning toward the 1:00 PM close too, so we can't pin the whole drop on stock.
A20: - | B20: Meanwhile 36 clickers were left for the blowout: Hot dog bun 12, WD-40 7, S'mores 6, Chocolate bar 4, Oreo 4, LEGO 2, Creeper cube 1. We printed about the right number of clickers in the wrong mix.
A22: Themes and pairings
A23: - | B23: Every Asian food design with a known count (Salmon nigiri, Dumpling, Spam musubi) sold out; Egg tart was restocked, so its count is unknown. Minecraft sold 95% of stock. Snacks & treats sold 62% (Avocado carried it). Workshop sold 53%.
A24: - | B24: Variety beat sets. Of the 35 sales with 2 or more items, 30 mixed designs and only 5 were several of one design. 23 sales mixed themes.
A25: - | B25: The most common theme mix was Asian food + Snacks & treats (12 sales).
A26: - | B26: Top pairs: Avocado + Dumpling (4 sales); Creeper + Dumpling, Avocado + Egg tart, Dumpling + Egg tart (3 each).
A27: - | B27: The mixers: Salmon nigiri showed up in 12 mixed sales alongside 10 different designs, and Dumpling in 11. They're the anchors kids built a 3-for-10 around.
A29: Who bought what (counted by customers, so one bulk buyer doesn't skew it)
A30: - | B30: Kids were the core: 32 of the 45 age-tagged sales. Teens 9, Adults 4.
A31: - | B31: Kids: Dumpling (9); Creeper, Hot dog bun, Salmon nigiri (6 each).
A32: - | B32: Teens: Salmon nigiri (6); Creeper infinity cube (2); 7 others (1 each).
A33: - | B33: Boys and men: Dumpling (8); Creeper (7); WD-40 (6).
A34: - | B34: Girls and women: Salmon nigiri (7); Egg tart (6); Dumpling (5).
A35: - | B35: Kid boys: Creeper, Dumpling, Hot dog bun (5 each).
A36: - | B36: Kid girls: Dumpling (4); Chocolate bar, Egg tart (3 each).
A37: - | B37: Creeper and WD-40 skewed boys (7 of 8 gender-tagged units each). Egg tart skewed girls (7 of 8).
A38: - | B38: Teens went for Salmon nigiri: 6 of 9 teen sales included one.
A39: - | B39: Every gender-tagged copter buyer was a boy.
A40: - | B40: Kid lumps elementary and middle schoolers into one bucket, which hides a lot. Next year: Elementary, Middle, and High school.
A42: Copters
A43: - | B43: 5 kits for 27 tickets, against roughly 450 net last year at the same prices. That's down about 95%.
A44: - | B44: 2 of the 5 kits were toroidal. 88 launchers, 155 propellers, 42 toroidal props, and 100 ripcords carry over. Don't buy more parts.
A46: Hypotheses to test
A47: - | B47: Clickers pulled the same kids and tickets copters used to get: they took 94% of the sales table's tickets. Test: sell copters at their own table or with a flying demo.
...

Sheet Leaderboard
A1: Leaderboard
A2: Ranked by sales rate: clickers sold per hour while the design was on the table. Fair across uneven stock.
A4: Rate rank | B4: Design | C4: Sales rate (units/hr) | D4: Sold out at | E4: Sell-through | F4: Units sold | G4: Starting stock | H4: Blended rank (70% rate) | I4: Notes
A5: ='Design Ranking'!R12 -> 1 | B5: ='Design Ranking'!A12 -> Dumpling | C5: ='Design Ranking'!L12 -> 7.1064935 | D5: =IF('Design Ranking'!H12="Unknown","Unknown",IF('Design Ranking'!I12="","Didn't",'Design Ranking'!I12)) -> 46312.529 | E5: =IF('Design Ranking'!G12="","Unknown",'Design Ranking'!G12) -> 1 | F5: ='Design Ranking'!E12 -> 24 | G5: =IF('Design Ranking'!C12="","Restocked",'Design Ranking'!C12) -> 24 | H5: ='Design Ranking'!P12 -> 1 | I5: =IF('Design Ranking'!S12="","",'Design Ranking'!S12) -> One parent bought the last 8 in one sale at 12:42 PM.
A6: ='Design Ranking'!R13 -> 2 | B6: ='Design Ranking'!A13 -> Salmon nigiri | C6: ='Design Ranking'!L13 -> 6.9433962 | D6: =IF('Design Ranking'!H13="Unknown","Unknown",IF('Design Ranking'!I13="","Didn't",'Design Ranking'!I13)) -> 46312.556 | E6: =IF('Design Ranking'!G13="","Unknown",'Design Ranking'!G13) -> 1 | F6: ='Design Ranking'!E13 -> 23 | G6: =IF('Design Ranking'!C13="","Restocked",'Design Ranking'!C13) -> 23 | H6: ='Design Ranking'!P13 -> 2 | I6: =IF('Design Ranking'!S13="","",'Design Ranking'!S13) -> Last 4 went at 1:20 PM: sold out right at the end.
A7: ='Design Ranking'!R14 -> 3 | B7: ='Design Ranking'!A14 -> Creeper | C7: ='Design Ranking'!L14 -> 5.6382146 | D7: =IF('Design Ranking'!H14="Unknown","Unknown",IF('Design Ranking'!I14="","Didn't",'Design Ranking'!I14)) -> 46312.492 | E7: =IF('Design Ranking'!G14="","Unknown",'Design Ranking'!G14) -> 1 | F7: ='Design Ranking'!E14 -> 10 | G7: =IF('Design Ranking'!C14="","Restocked",'Design Ranking'!C14) -> 10 | H7: ='Design Ranking'!P14 -> 3 | I7: =IF('Design Ranking'!S14="","",'Design Ranking'!S14) -> Sold out first (11:48 AM), no bulk buys.
A8: ='Design Ranking'!R15 -> 4 | B8: ='Design Ranking'!A15 -> Avocado | C8: ='Design Ranking'!L15 -> 4.4499382 | D8: =IF('Design Ranking'!H15="Unknown","Unknown",IF('Design Ranking'!I15="","Didn't",'Design Ranking'!I15)) -> 46312.53 | E8: =IF('Design Ranking'!G15="","Unknown",'Design Ranking'!G15) -> 1 | F8: ='Design Ranking'!E15 -> 12 | G8: =IF('Design Ranking'!C15="","Restocked",'Design Ranking'!C15) -> 12 | H8: ='Design Ranking'!P15 -> 4 | I8: =IF('Design Ranking'!S15="","",'Design Ranking'!S15) -> Last 3 went in one 3-for-10 sale at 12:43 PM.
A9: ='Design Ranking'!R16 -> 5 | B9: ='Design Ranking'!A16 -> Egg tart | C9: ='Design Ranking'!L16 -> 3.3207547 | D9: =IF('Design Ranking'!H16="Unknown","Unknown",IF('Design Ranking'!I16="","Didn't",'Design Ranking'!I16)) -> Unknown | E9: =IF('Design Ranking'!G16="","Unknown",'Design Ranking'!G16) -> Unknown | F9: ='Design Ranking'!E16 -> 11 | G9: =IF('Design Ranking'!C16="","Restocked",'Design Ranking'!C16) -> Restocked | H9: ='Design Ranking'!P16 -> 5 | I9: =IF('Design Ranking'!S16="","",'Design Ranking'!S16) -> Restocked day-of; sell-through unknown.
A10: ='Design Ranking'!R17 -> 5 | B10: ='Design Ranking'!A17 -> Chocolate bar | C10: ='Design Ranking'!L17 -> 3.3207547 | D10: =IF('Design Ranking'!H17="Unknown","Unknown",IF('Design Ranking'!I17="","Didn't",'Design Ranking'!I17)) -> Didn't | E10: =IF('Design Ranking'!G17="","Unknown",'Design Ranking'!G17) -> 0.73333333 | F10: ='Design Ranking'!E17 -> 11 | G10: =IF('Design Ranking'!C17="","Restocked",'Design Ranking'!C17) -> 15 | H10: ='Design Ranking'!P17 -> 5 | I10: =IF('Design Ranking'!S17="","",'Design Ranking'!S17)
A11: ='Design Ranking'!R18 -> 7 | B11: ='Design Ranking'!A18 -> Hot dog bun | C11: ='Design Ranking'!L18 -> 3.0188679 | D11: =IF('Design Ranking'!H18="Unknown","Unknown",IF('Design Ranking'!I18="","Didn't",'Design Ranking'!I18)) -> Didn't | E11: =IF('Design Ranking'!G18="","Unknown",'Design Ranking'!G18) -> 0.45454545 | F11: ='Design Ranking'!E18 -> 10 | G11: =IF('Design Ranking'!C18="","Restocked",'Design Ranking'!C18) -> 22 | H11: ='Design Ranking'!P18 -> 7 | I11: =IF('Design Ranking'!S18="","",'Design Ranking'!S18) -> Most units left over (12 of 22).
A12: ='Design Ranking'!R19 -> 8 | B12: ='Design Ranking'!A19 -> WD-40 | C12: ='Design Ranking'!L19 -> 2.4150943 | D12: =IF('Design Ranking'!H19="Unknown","Unknown",IF('Design Ranking'!I19="","Didn't",'Design Ranking'!I19)) -> Didn't | E12: =IF('Design Ranking'!G19="","Unknown",'Design Ranking'!G19) -> 0.53333333 | F12: ='Design Ranking'!E19 -> 8 | G12: =IF('Design Ranking'!C19="","Restocked",'Design Ranking'!C19) -> 15 | H12: ='Design Ranking'!P19 -> 8 | I12: =IF('Design Ranking'!S19="","",'Design Ranking'!S19)
A13: ='Design Ranking'!R20 -> 8 | B13: ='Design Ranking'!A20 -> Creeper infinity cube | C13: ='Design Ranking'!L20 -> 2.4150943 | D13: =IF('Design Ranking'!H20="Unknown","Unknown",IF('Design Ranking'!I20="","Didn't",'Design Ranking'!I20)) -> Didn't | E13: =IF('Design Ranking'!G20="","Unknown",'Design Ranking'!G20) -> 0.88888889 | F13: ='Design Ranking'!E20 -> 8 | G13: =IF('Design Ranking'!C20="","Restocked",'Design Ranking'!C20) -> 9 | H13: ='Design Ranking'!P20 -> 8 | I13: =IF('Design Ranking'!S20="","",'Design Ranking'!S20)
A14: ='Design Ranking'!R21 -> 10 | B14: ='Design Ranking'!A21 -> Spam musubi | C14: ='Design Ranking'!L21 -> 1.8113208 | D14: =IF('Design Ranking'!H21="Unknown","Unknown",IF('Design Ranking'!I21="","Didn't",'Design Ranking'!I21)) -> 46312.556 | E14: =IF('Design Ranking'!G21="","Unknown",'Design Ranking'!G21) -> 1 | F14: ='Design Ranking'!E21 -> 6 | G14: =IF('Design Ranking'!C21="","Restocked",'Design Ranking'!C21) -> 6 | H14: ='Design Ranking'!P21 -> 10 | I14: =IF('Design Ranking'!S21="","",'Design Ranking'!S21) -> Only 6 made; last 2 went at 1:20 PM.
A15: ='Design Ranking'!R22 -> 11 | B15: ='Design Ranking'!A22 -> S'mores | C15: ='Design Ranking'!L22 -> 0.90566038 | D15: =IF('Design Ranking'!H22="Unknown","Unknown",IF('Design Ranking'!I22="","Didn't",'Design Ranking'!I22)) -> Didn't | E15: =IF('Design Ranking'!G22="","Unknown",'Design Ranking'!G22) -> 0.33333333 | F15: ='Design Ranking'!E22 -> 3 | G15: =IF('Design Ranking'!C22="","Restocked",'Design Ranking'!C22) -> 9 | H15: ='Design Ranking'!P22 -> 11 | I15: =IF('Design Ranking'!S22="","",'Design Ranking'!S22)
A16: ='Design Ranking'!R23 -> 12 | B16: ='Design Ranking'!A23 -> LEGO brick | C16: ='Design Ranking'!L23 -> 0.60377358 | D16: =IF('Design Ranking'!H23="Unknown","Unknown",IF('Design Ranking'!I23="","Didn't",'Design Ranking'!I23)) -> Didn't | E16: =IF('Design Ranking'!G23="","Unknown",'Design Ranking'!G23) -> 0.5 | F16: ='Design Ranking'!E23 -> 2 | G16: =IF('Design Ranking'!C23="","Restocked",'Design Ranking'!C23) -> 4 | H16: ='Design Ranking'!P23 -> 12 | I16: =IF('Design Ranking'!S23="","",'Design Ranking'!S23) -> Both sales at 10:41 to 10:42 AM, then none. Worth checking if it got buried.
A18: Not ranked: Oreo (probably never put out) and Burger (not in the stock count, 1 sold).
A20: Most popular with each group
A21: Group | C21: Sales | D21: Clicker units | E21: Top designs (number of that group's sales that picked it)
A22: Kids | C22: =COUNTIFS(Baskets!$E$2:$E$70,"Kid") -> 32 | D22: =SUMIFS('Raw Data'!$F$2:$F$114,'Raw Data'!$D$2:$D$114,"Clickers & Fidget Toys",'Raw Data'!$I$2:$I$114,"Kid") -> 53 | E22: Dumpling (9); Creeper, Hot dog bun, Salmon nigiri (6 each)
A23: Teens | C23: =COUNTIFS(Baskets!$E$2:$E$70,"Teen") -> 9 | D23: =SUMIFS('Raw Data'!$F$2:$F$114,'Raw Data'!$D$2:$D$114,"Clickers & Fidget Toys",'Raw Data'!$I$2:$I$114,"Teen") -> 19 | E23: Salmon nigiri (6); Creeper infinity cube (2); 7 others (1 each)
A24: Adults | C24: =COUNTIFS(Baskets!$E$2:$E$70,"Adult") -> 4 | D24: =SUMIFS('Raw Data'!$F$2:$F$114,'Raw Data'!$D$2:$D$114,"Clickers & Fidget Toys",'Raw Data'!$I$2:$I$114,"Adult") -> 8 | E24: Salmon nigiri (2); 5 others (1 each)
A25: Boys and men | C25: =COUNTIFS(Baskets!$F$2:$F$70,"Male") -> 28 | D25: =SUMIFS('Raw Data'!$F$2:$F$114,'Raw Data'!$D$2:$D$114,"Clickers & Fidget Toys",'Raw Data'!$J$2:$J$114,"Male") -> 51 | E25: Dumpling (8); Creeper (7); WD-40 (6)
A26: Girls and women | C26: =COUNTIFS(Baskets!$F$2:$F$70,"Female") -> 18 | D26: =SUMIFS('Raw Data'!$F$2:$F$114,'Raw Data'!$D$2:$D$114,"Clickers & Fidget Toys",'Raw Data'!$J$2:$J$114,"Female") -> 36 | E26: Salmon nigiri (7); Egg tart (6); Dumpling (5)
A27: Kid boys | C27: =COUNTIFS(Baskets!$E$2:$E$70,"Kid",Baskets!$F$2:$F$70,"Male") -> 19 | D27: =SUMIFS('Raw Data'!$F$2:$F$114,'Raw Data'!$D$2:$D$114,"Clickers & Fidget Toys",'Raw Data'!$I$2:$I$114,"Kid",'Raw Data'!$J$2:$J$114,"Male") -> 28 | E27: Creeper, Dumpling, Hot dog bun (5 each)
A28: Kid girls | C28: =COUNTIFS(Baskets!$E$2:$E$70,"Kid",Baskets!$F$2:$F$70,"Female") -> 11 | D28: =SUMIFS('Raw Data'!$F$2:$F$114,'Raw Data'!$D$2:$D$114,"Clickers & Fidget Toys",'Raw Data'!$I$2:$I$114,"Kid",'Raw Data'!$J$2:$J$114,"Female") -> 20 | E28: Dumpling (4); Chocolate bar, Egg tart (3 each)
A29: Teen boys | C29: =COUNTIFS(Baskets!$E$2:$E$70,"Teen",Baskets!$F$2:$F$70,"Male") -> 4 | D29: =SUMIFS('Raw Data'!$F$2:$F$114,'Raw Data'!$D$2:$D$114,"Clickers & Fidget Toys",'Raw Data'!$I$2:$I$114,"Teen",'Raw Data'!$J$2:$J$114,"Male") -> 7 | E29: Creeper infinity cube, Salmon nigiri (2 each); Avocado, Creeper (1 each)
A30: Teen girls | C30: =COUNTIFS(Baskets!$E$2:$E$70,"Teen",Baskets!$F$2:$F$70,"Female") -> 4 | D30: =SUMIFS('Raw Data'!$F$2:$F$114,'Raw Data'!$D$2:$D$114,"Clickers & Fidget Toys",'Raw Data'!$I$2:$I$114,"Teen",'Raw Data'!$J$2:$J$114,"Female") -> 9 | E30: Salmon nigiri (3); 5 others (1 each)
A31: Adult men | C31: =COUNTIFS(Baskets!$E$2:$E$70,"Adult",Baskets!$F$2:$F$70,"Male") -> 2 | D31: =SUMIFS('Raw Data'!$F$2:$F$114,'Raw Data'!$D$2:$D$114,"Clickers & Fidget Toys",'Raw Data'!$I$2:$I$114,"Adult",'Raw Data'!$J$2:$J$114,"Male") -> 3 | E31: Creeper, Dumpling, WD-40 (1 each)
A32: Adult women | C32: =COUNTIFS(Baskets!$E$2:$E$70,"Adult",Baskets!$F$2:$F$70,"Female") -> 2 | D32: =SUMIFS('Raw Data'!$F$2:$F$114,'Raw Data'!$D$2:$D$114,"Clickers & Fidget Toys",'Raw Data'!$I$2:$I$114,"Adult",'Raw Data'!$J$2:$J$114,"Female") -> 5 | E32: Salmon nigiri (2); Egg tart, Spam musubi (1 each)
A34: Untagged sales aren't in any group. Groups under about 5 sales are hints, not findings. Next year, split Kid into Elementary, Middle, and High school.

Sheet Design Ranking
A1: Clicker design ranking
A2: Sorted by sales rate. Blended score = rate weight x (rate / best rate) + volume weight x (units / most units), out of 100.
A4: Rate weight | B4: 0.7
A5: Volume weight | B5: =1-B4 -> 0.3
A6: Max units of one design per sale counted toward rate | B6: 3
A7: Selling window start | B7: =MIN('Raw Data'!$B$2:$B$114) -> 46312.418
A8: Selling window end | B8: =MAX('Raw Data'!$C$2:$C$114) -> 46312.556
A9: Window hours | B9: =(B8-B7)*24 -> 3.3125
A11: Design | B11: Theme | C11: Starting stock | D11: On table from | E11: Units sold | F11: Tickets rung up | G11: Sell-through | H11: Sold out? | I11: Sold out at | J11: Hours in stock | K11: Units counted for rate | L11: Sales rate (units/hr) | M11: Rate score | N11: Volume score | O11: Blended score | P11: Blended rank | Q11: Units rank | R11: Rate rank | S11: Notes
A12: Dumpling | B12: Asian food | C12: 24 | D12: =$B$7 -> 46312.418 | E12: =SUMIFS('Raw Data'!$F$2:$F$114,'Raw Data'!$E$2:$E$114,A12) -> 24 | F12: =SUMIFS('Raw Data'!$G$2:$G$114,'Raw Data'!$E$2:$E$114,A12) -> 80 | G12: =IF(C12="","",E12/C12) -> 1 | H12: =IF(C12="","Unknown",IF(E12>=C12,"Yes","No")) -> Yes | I12: =IF(H12="Yes",SUMPRODUCT(MAX(('Raw Data'!$E$2:$E$114=A12)*'Raw Data'!$C$2:$C$114)),"") -> 46312.529 | J12: =IF(H12="Yes",(I12-D12)*24,($B$8-D12)*24) -> 2.6736111 | K12: =SUMIFS('Raw Data'!$M$2:$M$114,'Raw Data'!$E$2:$E$114,A12) -> 19 | L12: =IF(J12>0,K12/J12,0) -> 7.1064935 | M12: =L12/MAX($L$12:$L$23) -> 1 | N12: =E12/MAX($E$12:$E$23) -> 1 | O12: =100*($B$4*M12+$B$5*N12) -> 100 | P12: =RANK(O12,$O$12:$O$23) -> 1 | Q12: =RANK(E12,$E$12:$E$23) -> 1 | R12: =RANK(L12,$L$12:$L$23) -> 1 | S12: One parent bought the last 8 in one sale at 12:42 PM.
A13: Salmon nigiri | B13: Asian food | C13: 23 | D13: =$B$7 -> 46312.418 | E13: =SUMIFS('Raw Data'!$F$2:$F$114,'Raw Data'!$E$2:$E$114,A13) -> 23 | F13: =SUMIFS('Raw Data'!$G$2:$G$114,'Raw Data'!$E$2:$E$114,A13) -> 77 | G13: =IF(C13="","",E13/C13) -> 1 | H13: =IF(C13="","Unknown",IF(E13>=C13,"Yes","No")) -> Yes | I13: =IF(H13="Yes",SUMPRODUCT(MAX(('Raw Data'!$E$2:$E$114=A13)*'Raw Data'!$C$2:$C$114)),"") -> 46312.556 | J13: =IF(H13="Yes",(I13-D13)*24,($B$8-D13)*24) -> 3.3125 | K13: =SUMIFS('Raw Data'!$M$2:$M$114,'Raw Data'!$E$2:$E$114,A13) -> 23 | L13: =IF(J13>0,K13/J13,0) -> 6.9433962 | M13: =L13/MAX($L$12:$L$23) -> 0.97704954 | N13: =E13/MAX($E$12:$E$23) -> 0.95833333 | O13: =100*($B$4*M13+$B$5*N13) -> 97.143468 | P13: =RANK(O13,$O$12:$O$23) -> 2 | Q13: =RANK(E13,$E$12:$E$23) -> 2 | R13: =RANK(L13,$L$12:$L$23) -> 2 | S13: Last 4 went at 1:20 PM: sold out right at the end.
A14: Creeper | B14: Minecraft | C14: 10 | D14: =$B$7 -> 46312.418 | E14: =SUMIFS('Raw Data'!$F$2:$F$114,'Raw Data'!$E$2:$E$114,A14) -> 10 | F14: =SUMIFS('Raw Data'!$G$2:$G$114,'Raw Data'!$E$2:$E$114,A14) -> 37 | G14: =IF(C14="","",E14/C14) -> 1 | H14: =IF(C14="","Unknown",IF(E14>=C14,"Yes","No")) -> Yes | I14: =IF(H14="Yes",SUMPRODUCT(MAX(('Raw Data'!$E$2:$E$114=A14)*'Raw Data'!$C$2:$C$114)),"") -> 46312.492 | J14: =IF(H14="Yes",(I14-D14)*24,($B$8-D14)*24) -> 1.7736111 | K14: =SUMIFS('Raw Data'!$M$2:$M$114,'Raw Data'!$E$2:$E$114,A14) -> 10 | L14: =IF(J14>0,K14/J14,0) -> 5.6382146 | M14: =L14/MAX($L$12:$L$23) -> 0.79338911 | N14: =E14/MAX($E$12:$E$23) -> 0.41666667 | O14: =100*($B$4*M14+$B$5*N14) -> 68.037238 | P14: =RANK(O14,$O$12:$O$23) -> 3 | Q14: =RANK(E14,$E$12:$E$23) -> 6 | R14: =RANK(L14,$L$12:$L$23) -> 3 | S14: Sold out first (11:48 AM), no bulk buys.
A15: Avocado | B15: Snacks & treats | C15: 12 | D15: =$B$7 -> 46312.418 | E15: =SUMIFS('Raw Data'!$F$2:$F$114,'Raw Data'!$E$2:$E$114,A15) -> 12 | F15: =SUMIFS('Raw Data'!$G$2:$G$114,'Raw Data'!$E$2:$E$114,A15) -> 42 | G15: =IF(C15="","",E15/C15) -> 1 | H15: =IF(C15="","Unknown",IF(E15>=C15,"Yes","No")) -> Yes | I15: =IF(H15="Yes",SUMPRODUCT(MAX(('Raw Data'!$E$2:$E$114=A15)*'Raw Data'!$C$2:$C$114)),"") -> 46312.53 | J15: =IF(H15="Yes",(I15-D15)*24,($B$8-D15)*24) -> 2.6966667 | K15: =SUMIFS('Raw Data'!$M$2:$M$114,'Raw Data'!$E$2:$E$114,A15) -> 12 | L15: =IF(J15>0,K15/J15,0) -> 4.4499382 | M15: =L15/MAX($L$12:$L$23) -> 0.62617917 | N15: =E15/MAX($E$12:$E$23) -> 0.5 | O15: =100*($B$4*M15+$B$5*N15) -> 58.832542 | P15: =RANK(O15,$O$12:$O$23) -> 4 | Q15: =RANK(E15,$E$12:$E$23) -> 3 | R15: =RANK(L15,$L$12:$L$23) -> 4 | S15: Last 3 went in one 3-for-10 sale at 12:43 PM.
A16: Egg tart | B16: Asian food | D16: =$B$7 -> 46312.418 | E16: =SUMIFS('Raw Data'!$F$2:$F$114,'Raw Data'!$E$2:$E$114,A16) -> 11 | F16: =SUMIFS('Raw Data'!$G$2:$G$114,'Raw Data'!$E$2:$E$114,A16) -> 40 | G16: =IF(C16="","",E16/C16) | H16: =IF(C16="","Unknown",IF(E16>=C16,"Yes","No")) -> Unknown | I16: =IF(H16="Yes",SUMPRODUCT(MAX(('Raw Data'!$E$2:$E$114=A16)*'Raw Data'!$C$2:$C$114)),"") | J16: =IF(H16="Yes",(I16-D16)*24,($B$8-D16)*24) -> 3.3125 | K16: =SUMIFS('Raw Data'!$M$2:$M$114,'Raw Data'!$E$2:$E$114,A16) -> 11 | L16: =IF(J16>0,K16/J16,0) -> 3.3207547 | M16: =L16/MAX($L$12:$L$23) -> 0.46728456 | N16: =E16/MAX($E$12:$E$23) -> 0.45833333 | O16: =100*($B$4*M16+$B$5*N16) -> 46.459919 | P16: =RANK(O16,$O$12:$O$23) -> 5 | Q16: =RANK(E16,$E$12:$E$23) -> 4 | R16: =RANK(L16,$L$12:$L$23) -> 5 | S16: Restocked day-of; sell-through unknown.
A17: Chocolate bar | B17: Snacks & treats | C17: 15 | D17: =$B$7 -> 46312.418 | E17: =SUMIFS('Raw Data'!$F$2:$F$114,'Raw Data'!$E$2:$E$114,A17) -> 11 | F17: =SUMIFS('Raw Data'!$G$2:$G$114,'Raw Data'!$E$2:$E$114,A17) -> 42 | G17: =IF(C17="","",E17/C17) -> 0.73333333 | H17: =IF(C17="","Unknown",IF(E17>=C17,"Yes","No")) -> No | I17: =IF(H17="Yes",SUMPRODUCT(MAX(('Raw Data'!$E$2:$E$114=A17)*'Raw Data'!$C$2:$C$114)),"") | J17: =IF(H17="Yes",(I17-D17)*24,($B$8-D17)*24) -> 3.3125 | K17: =SUMIFS('Raw Data'!$M$2:$M$114,'Raw Data'!$E$2:$E$114,A17) -> 11 | L17: =IF(J17>0,K17/J17,0) -> 3.3207547 | M17: =L17/MAX($L$12:$L$23) -> 0.46728456 | N17: =E17/MAX($E$12:$E$23) -> 0.45833333 | O17: =100*($B$4*M17+$B$5*N17) -> 46.459919 | P17: =RANK(O17,$O$12:$O$23) -> 5 | Q17: =RANK(E17,$E$12:$E$23) -> 4 | R17: =RANK(L17,$L$12:$L$23) -> 5
A18: Hot dog bun | B18: Snacks & treats | C18: 22 | D18: =$B$7 -> 46312.418 | E18: =SUMIFS('Raw Data'!$F$2:$F$114,'Raw Data'!$E$2:$E$114,A18) -> 10 | F18: =SUMIFS('Raw Data'!$G$2:$G$114,'Raw Data'!$E$2:$E$114,A18) -> 36 | G18: =IF(C18="","",E18/C18) -> 0.45454545 | H18: =IF(C18="","Unknown",IF(E18>=C18,"Yes","No")) -> No | I18: =IF(H18="Yes",SUMPRODUCT(MAX(('Raw Data'!$E$2:$E$114=A18)*'Raw Data'!$C$2:$C$114)),"") | J18: =IF(H18="Yes",(I18-D18)*24,($B$8-D18)*24) -> 3.3125 | K18: =SUMIFS('Raw Data'!$M$2:$M$114,'Raw Data'!$E$2:$E$114,A18) -> 10 | L18: =IF(J18>0,K18/J18,0) -> 3.0188679 | M18: =L18/MAX($L$12:$L$23) -> 0.42480415 | N18: =E18/MAX($E$12:$E$23) -> 0.41666667 | O18: =100*($B$4*M18+$B$5*N18) -> 42.23629 | P18: =RANK(O18,$O$12:$O$23) -> 7 | Q18: =RANK(E18,$E$12:$E$23) -> 6 | R18: =RANK(L18,$L$12:$L$23) -> 7 | S18: Most units left over (12 of 22).
A19: WD-40 | B19: Workshop | C19: 15 | D19: =$B$7 -> 46312.418 | E19: =SUMIFS('Raw Data'!$F$2:$F$114,'Raw Data'!$E$2:$E$114,A19) -> 8 | F19: =SUMIFS('Raw Data'!$G$2:$G$114,'Raw Data'!$E$2:$E$114,A19) -> 27 | G19: =IF(C19="","",E19/C19) -> 0.53333333 | H19: =IF(C19="","Unknown",IF(E19>=C19,"Yes","No")) -> No | I19: =IF(H19="Yes",SUMPRODUCT(MAX(('Raw Data'!$E$2:$E$114=A19)*'Raw Data'!$C$2:$C$114)),"") | J19: =IF(H19="Yes",(I19-D19)*24,($B$8-D19)*24) -> 3.3125 | K19: =SUMIFS('Raw Data'!$M$2:$M$114,'Raw Data'!$E$2:$E$114,A19) -> 8 | L19: =IF(J19>0,K19/J19,0) -> 2.4150943 | M19: =L19/MAX($L$12:$L$23) -> 0.33984332 | N19: =E19/MAX($E$12:$E$23) -> 0.33333333 | O19: =100*($B$4*M19+$B$5*N19) -> 33.789032 | P19: =RANK(O19,$O$12:$O$23) -> 8 | Q19: =RANK(E19,$E$12:$E$23) -> 8 | R19: =RANK(L19,$L$12:$L$23) -> 8
A20: Creeper infinity cube | B20: Minecraft | C20: 9 | D20: =$B$7 -> 46312.418 | E20: =SUMIFS('Raw Data'!$F$2:$F$114,'Raw Data'!$E$2:$E$114,A20) -> 8 | F20: =SUMIFS('Raw Data'!$G$2:$G$114,'Raw Data'!$E$2:$E$114,A20) -> 30 | G20: =IF(C20="","",E20/C20) -> 0.88888889 | H20: =IF(C20="","Unknown",IF(E20>=C20,"Yes","No")) -> No | I20: =IF(H20="Yes",SUMPRODUCT(MAX(('Raw Data'!$E$2:$E$114=A20)*'Raw Data'!$C$2:$C$114)),"") | J20: =IF(H20="Yes",(I20-D20)*24,($B$8-D20)*24) -> 3.3125 | K20: =SUMIFS('Raw Data'!$M$2:$M$114,'Raw Data'!$E$2:$E$114,A20) -> 8 | L20: =IF(J20>0,K20/J20,0) -> 2.4150943 | M20: =L20/MAX($L$12:$L$23) -> 0.33984332 | N20: =E20/MAX($E$12:$E$23) -> 0.33333333 | O20: =100*($B$4*M20+$B$5*N20) -> 33.789032 | P20: =RANK(O20,$O$12:$O$23) -> 8 | Q20: =RANK(E20,$E$12:$E$23) -> 8 | R20: =RANK(L20,$L$12:$L$23) -> 8
A21: Spam musubi | B21: Asian food | C21: 6 | D21: =$B$7 -> 46312.418 | E21: =SUMIFS('Raw Data'!$F$2:$F$114,'Raw Data'!$E$2:$E$114,A21) -> 6 | F21: =SUMIFS('Raw Data'!$G$2:$G$114,'Raw Data'!$E$2:$E$114,A21) -> 23 | G21: =IF(C21="","",E21/C21) -> 1 | H21: =IF(C21="","Unknown",IF(E21>=C21,"Yes","No")) -> Yes | I21: =IF(H21="Yes",SUMPRODUCT(MAX(('Raw Data'!$E$2:$E$114=A21)*'Raw Data'!$C$2:$C$114)),"") -> 46312.556 | J21: =IF(H21="Yes",(I21-D21)*24,($B$8-D21)*24) -> 3.3125 | K21: =SUMIFS('Raw Data'!$M$2:$M$114,'Raw Data'!$E$2:$E$114,A21) -> 6 | L21: =IF(J21>0,K21/J21,0) -> 1.8113208 | M21: =L21/MAX($L$12:$L$23) -> 0.25488249 | N21: =E21/MAX($E$12:$E$23) -> 0.25 | O21: =100*($B$4*M21+$B$5*N21) -> 25.341774 | P21: =RANK(O21,$O$12:$O$23) -> 10 | Q21: =RANK(E21,$E$12:$E$23) -> 10 | R21: =RANK(L21,$L$12:$L$23) -> 10 | S21: Only 6 made; last 2 went at 1:20 PM.
A22: S'mores | B22: Snacks & treats | C22: 9 | D22: =$B$7 -> 46312.418 | E22: =SUMIFS('Raw Data'!$F$2:$F$114,'Raw Data'!$E$2:$E$114,A22) -> 3 | F22: =SUMIFS('Raw Data'!$G$2:$G$114,'Raw Data'!$E$2:$E$114,A22) -> 11 | G22: =IF(C22="","",E22/C22) -> 0.33333333 | H22: =IF(C22="","Unknown",IF(E22>=C22,"Yes","No")) -> No | I22: =IF(H22="Yes",SUMPRODUCT(MAX(('Raw Data'!$E$2:$E$114=A22)*'Raw Data'!$C$2:$C$114)),"") | J22: =IF(H22="Yes",(I22-D22)*24,($B$8-D22)*24) -> 3.3125 | K22: =SUMIFS('Raw Data'!$M$2:$M$114,'Raw Data'!$E$2:$E$114,A22) -> 3 | L22: =IF(J22>0,K22/J22,0) -> 0.90566038 | M22: =L22/MAX($L$12:$L$23) -> 0.12744124 | N22: =E22/MAX($E$12:$E$23) -> 0.125 | O22: =100*($B$4*M22+$B$5*N22) -> 12.670887 | P22: =RANK(O22,$O$12:$O$23) -> 11 | Q22: =RANK(E22,$E$12:$E$23) -> 11 | R22: =RANK(L22,$L$12:$L$23) -> 11
A23: LEGO brick | B23: Workshop | C23: 4 | D23: =$B$7 -> 46312.418 | E23: =SUMIFS('Raw Data'!$F$2:$F$114,'Raw Data'!$E$2:$E$114,A23) -> 2 | F23: =SUMIFS('Raw Data'!$G$2:$G$114,'Raw Data'!$E$2:$E$114,A23) -> 6 | G23: =IF(C23="","",E23/C23) -> 0.5 | H23: =IF(C23="","Unknown",IF(E23>=C23,"Yes","No")) -> No | I23: =IF(H23="Yes",SUMPRODUCT(MAX(('Raw Data'!$E$2:$E$114=A23)*'Raw Data'!$C$2:$C$114)),"") | J23: =IF(H23="Yes",(I23-D23)*24,($B$8-D23)*24) -> 3.3125 | K23: =SUMIFS('Raw Data'!$M$2:$M$114,'Raw Data'!$E$2:$E$114,A23) -> 2 | L23: =IF(J23>0,K23/J23,0) -> 0.60377358 | M23: =L23/MAX($L$12:$L$23) -> 0.08496083 | N23: =E23/MAX($E$12:$E$23) -> 0.083333333 | O23: =100*($B$4*M23+$B$5*N23) -> 8.4472581 | P23: =RANK(O23,$O$12:$O$23) -> 12 | Q23: =RANK(E23,$E$12:$E$23) -> 12 | R23: =RANK(L23,$L$12:$L$23) -> 12 | S23: Both sales at 10:41 to 10:42 AM, then none. Worth checking if it got buried.
A24: Oreo | B24: Snacks & treats | C24: 4 | D24: =$B$7 -> 46312.418 | E24: =SUMIFS('Raw Data'!$F$2:$F$114,'Raw Data'!$E$2:$E$114,A24) -> 0 | F24: =SUMIFS('Raw Data'!$G$2:$G$114,'Raw Data'!$E$2:$E$114,A24) -> 0 | G24: =IF(C24="","",E24/C24) -> 0 | H24: =IF(C24="","Unknown",IF(E24>=C24,"Yes","No")) -> No | I24: =IF(H24="Yes",SUMPRODUCT(MAX(('Raw Data'!$E$2:$E$114=A24)*'Raw Data'!$C$2:$C$114)),"") | J24: =IF(H24="Yes",(I24-D24)*24,($B$8-D24)*24) -> 3.3125 | K24: =SUMIFS('Raw Data'!$M$2:$M$114,'Raw Data'!$E$2:$E$114,A24) -> 0 | L24: =IF(J24>0,K24/J24,0) -> 0 | S24: Not ranked: probably never put out on the table (Sam).
A25: Burger | B25: Snacks & treats | D25: =$B$7 -> 46312.418 | E25: =SUMIFS('Raw Data'!$F$2:$F$114,'Raw Data'!$E$2:$E$114,A25) -> 1 | F25: =SUMIFS('Raw Data'!$G$2:$G$114,'Raw Data'!$E$2:$E$114,A25) -> 4 | G25: =IF(C25="","",E25/C25) | H25: =IF(C25="","Unknown",IF(E25>=C25,"Yes","No")) -> Unknown | I25: =IF(H25="Yes",SUMPRODUCT(MAX(('Raw Data'!$E$2:$E$114=A25)*'Raw Data'!$C$2:$C$114)),"") | J25: =IF(H25="Yes",(I25-D25)*24,($B$8-D25)*24) -> 3.3125 | K25: =SUMIFS('Raw Data'!$M$2:$M$114,'Raw Data'!$E$2:$E$114,A25) -> 1 | L25: =IF(J25>0,K25/J25,0) -> 0.30188679 | S25: Not ranked: not in the stock count, 1 sold.

Sheet Stock & Lost Sales
A1: What we ran short on, and what it cost
A2: Lost units = sales rate x hours the design was gone before the last sale of the day. Ideal stock = rate x window x (1 + buffer).
A4: Buffer for next year's stock | B4: 0.2
A5: Avg tickets per clicker (this year) | B5: =SUMIFS('Raw Data'!$G$2:$G$114,'Raw Data'!$D$2:$D$114,"Clickers & Fidget Toys")/SUMIFS('Raw Data'!$F$2:$F$114,'Raw Data'!$D$2:$D$114,"Clickers & Fidget Toys") -> 3.5271318
A6: Window hours | B6: ='Design Ranking'!B9 -> 3.3125
A8: Design | B8: Starting stock | C8: Units sold | D8: Left over | E8: Sold out at | F8: Hours sold out | G8: Sales rate (units/hr) | H8: Lost units | I8: Lost tickets | J8: Ideal stock next year | K8: Change vs this year
A9: ='Design Ranking'!A12 -> Dumpling | B9: =IF('Design Ranking'!C12="","",'Design Ranking'!C12) -> 24 | C9: ='Design Ranking'!E12 -> 24 | D9: =IF(B9="","",MAX(0,B9-C9)) -> 0 | E9: ='Design Ranking'!I12 -> 46312.529 | F9: =IF('Design Ranking'!H12="Yes",('Design Ranking'!$B$8-'Design Ranking'!I12)*24,0) -> 0.63888889 | G9: ='Design Ranking'!L12 -> 7.1064935 | H9: =G9*F9 -> 4.5402597 | I9: =H9*$B$5 -> 16.014094 | J9: =ROUNDUP(G9*$B$6*(1+$B$4),0) -> 29 | K9: =IF(B9="","",J9-B9) -> 5
A10: ='Design Ranking'!A13 -> Salmon nigiri | B10: =IF('Design Ranking'!C13="","",'Design Ranking'!C13) -> 23 | C10: ='Design Ranking'!E13 -> 23 | D10: =IF(B10="","",MAX(0,B10-C10)) -> 0 | E10: ='Design Ranking'!I13 -> 46312.556 | F10: =IF('Design Ranking'!H13="Yes",('Design Ranking'!$B$8-'Design Ranking'!I13)*24,0) -> 0 | G10: ='Design Ranking'!L13 -> 6.9433962 | H10: =G10*F10 -> 0 | I10: =H10*$B$5 -> 0 | J10: =ROUNDUP(G10*$B$6*(1+$B$4),0) -> 28 | K10: =IF(B10="","",J10-B10) -> 5
A11: ='Design Ranking'!A14 -> Creeper | B11: =IF('Design Ranking'!C14="","",'Design Ranking'!C14) -> 10 | C11: ='Design Ranking'!E14 -> 10 | D11: =IF(B11="","",MAX(0,B11-C11)) -> 0 | E11: ='Design Ranking'!I14 -> 46312.492 | F11: =IF('Design Ranking'!H14="Yes",('Design Ranking'!$B$8-'Design Ranking'!I14)*24,0) -> 1.5388889 | G11: ='Design Ranking'!L14 -> 5.6382146 | H11: =G11*F11 -> 8.6765857 | I11: =H11*$B$5 -> 30.603461 | J11: =ROUNDUP(G11*$B$6*(1+$B$4),0) -> 23 | K11: =IF(B11="","",J11-B11) -> 13
A12: ='Design Ranking'!A15 -> Avocado | B12: =IF('Design Ranking'!C15="","",'Design Ranking'!C15) -> 12 | C12: ='Design Ranking'!E15 -> 12 | D12: =IF(B12="","",MAX(0,B12-C12)) -> 0 | E12: ='Design Ranking'!I15 -> 46312.53 | F12: =IF('Design Ranking'!H15="Yes",('Design Ranking'!$B$8-'Design Ranking'!I15)*24,0) -> 0.61583333 | G12: ='Design Ranking'!L15 -> 4.4499382 | H12: =G12*F12 -> 2.7404203 | I12: =H12*$B$5 -> 9.6658234 | J12: =ROUNDUP(G12*$B$6*(1+$B$4),0) -> 18 | K12: =IF(B12="","",J12-B12) -> 6
A13: ='Design Ranking'!A16 -> Egg tart | B13: =IF('Design Ranking'!C16="","",'Design Ranking'!C16) | C13: ='Design Ranking'!E16 -> 11 | D13: =IF(B13="","",MAX(0,B13-C13)) | E13: ='Design Ranking'!I16 | F13: =IF('Design Ranking'!H16="Yes",('Design Ranking'!$B$8-'Design Ranking'!I16)*24,0) -> 0 | G13: ='Design Ranking'!L16 -> 3.3207547 | H13: =G13*F13 -> 0 | I13: =H13*$B$5 -> 0 | J13: =ROUNDUP(G13*$B$6*(1+$B$4),0) -> 14 | K13: =IF(B13="","",J13-B13)
A14: ='Design Ranking'!A17 -> Chocolate bar | B14: =IF('Design Ranking'!C17="","",'Design Ranking'!C17) -> 15 | C14: ='Design Ranking'!E17 -> 11 | D14: =IF(B14="","",MAX(0,B14-C14)) -> 4 | E14: ='Design Ranking'!I17 | F14: =IF('Design Ranking'!H17="Yes",('Design Ranking'!$B$8-'Design Ranking'!I17)*24,0) -> 0 | G14: ='Design Ranking'!L17 -> 3.3207547 | H14: =G14*F14 -> 0 | I14: =H14*$B$5 -> 0 | J14: =ROUNDUP(G14*$B$6*(1+$B$4),0) -> 14 | K14: =IF(B14="","",J14-B14) -> -1
A15: ='Design Ranking'!A18 -> Hot dog bun | B15: =IF('Design Ranking'!C18="","",'Design Ranking'!C18) -> 22 | C15: ='Design Ranking'!E18 -> 10 | D15: =IF(B15="","",MAX(0,B15-C15)) -> 12 | E15: ='Design Ranking'!I18 | F15: =IF('Design Ranking'!H18="Yes",('Design Ranking'!$B$8-'Design Ranking'!I18)*24,0) -> 0 | G15: ='Design Ranking'!L18 -> 3.0188679 | H15: =G15*F15 -> 0 | I15: =H15*$B$5 -> 0 | J15: =ROUNDUP(G15*$B$6*(1+$B$4),0) -> 12 | K15: =IF(B15="","",J15-B15) -> -10
A16: ='Design Ranking'!A19 -> WD-40 | B16: =IF('Design Ranking'!C19="","",'Design Ranking'!C19) -> 15 | C16: ='Design Ranking'!E19 -> 8 | D16: =IF(B16="","",MAX(0,B16-C16)) -> 7 | E16: ='Design Ranking'!I19 | F16: =IF('Design Ranking'!H19="Yes",('Design Ranking'!$B$8-'Design Ranking'!I19)*24,0) -> 0 | G16: ='Design Ranking'!L19 -> 2.4150943 | H16: =G16*F16 -> 0 | I16: =H16*$B$5 -> 0 | J16: =ROUNDUP(G16*$B$6*(1+$B$4),0) -> 10 | K16: =IF(B16="","",J16-B16) -> -5
A17: ='Design Ranking'!A20 -> Creeper infinity cube | B17: =IF('Design Ranking'!C20="","",'Design Ranking'!C20) -> 9 | C17: ='Design Ranking'!E20 -> 8 | D17: =IF(B17="","",MAX(0,B17-C17)) -> 1 | E17: ='Design Ranking'!I20 | F17: =IF('Design Ranking'!H20="Yes",('Design Ranking'!$B$8-'Design Ranking'!I20)*24,0) -> 0 | G17: ='Design Ranking'!L20 -> 2.4150943 | H17: =G17*F17 -> 0 | I17: =H17*$B$5 -> 0 | J17: =ROUNDUP(G17*$B$6*(1+$B$4),0) -> 10 | K17: =IF(B17="","",J17-B17) -> 1
A18: ='Design Ranking'!A21 -> Spam musubi | B18: =IF('Design Ranking'!C21="","",'Design Ranking'!C21) -> 6 | C18: ='Design Ranking'!E21 -> 6 | D18: =IF(B18="","",MAX(0,B18-C18)) -> 0 | E18: ='Design Ranking'!I21 -> 46312.556 | F18: =IF('Design Ranking'!H21="Yes",('Design Ranking'!$B$8-'Design Ranking'!I21)*24,0) -> 0 | G18: ='Design Ranking'!L21 -> 1.8113208 | H18: =G18*F18 -> 0 | I18: =H18*$B$5 -> 0 | J18: =ROUNDUP(G18*$B$6*(1+$B$4),0) -> 8 | K18: =IF(B18="","",J18-B18) -> 2
A19: ='Design Ranking'!A22 -> S'mores | B19: =IF('Design Ranking'!C22="","",'Design Ranking'!C22) -> 9 | C19: ='Design Ranking'!E22 -> 3 | D19: =IF(B19="","",MAX(0,B19-C19)) -> 6 | E19: ='Design Ranking'!I22 | F19: =IF('Design Ranking'!H22="Yes",('Design Ranking'!$B$8-'Design Ranking'!I22)*24,0) -> 0 | G19: ='Design Ranking'!L22 -> 0.90566038 | H19: =G19*F19 -> 0 | I19: =H19*$B$5 -> 0 | J19: =ROUNDUP(G19*$B$6*(1+$B$4),0) -> 4 | K19: =IF(B19="","",J19-B19) -> -5
A20: ='Design Ranking'!A23 -> LEGO brick | B20: =IF('Design Ranking'!C23="","",'Design Ranking'!C23) -> 4 | C20: ='Design Ranking'!E23 -> 2 | D20: =IF(B20="","",MAX(0,B20-C20)) -> 2 | E20: ='Design Ranking'!I23 | F20: =IF('Design Ranking'!H23="Yes",('Design Ranking'!$B$8-'Design Ranking'!I23)*24,0) -> 0 | G20: ='Design Ranking'!L23 -> 0.60377358 | H20: =G20*F20 -> 0 | I20: =H20*$B$5 -> 0 | J20: =ROUNDUP(G20*$B$6*(1+$B$4),0) -> 3 | K20: =IF(B20="","",J20-B20) -> -1
A21: Total | B21: =SUM(B9:B20) -> 149 | C21: =SUM(C9:C20) -> 128 | D21: =SUM(D9:D20) -> 32 | H21: =SUM(H9:H20) -> 15.957266 | I21: =SUM(I9:I20) -> 56.283379 | J21: =SUM(J9:J20) -> 173
A22: Oreo (not put out) | B22: ='Design Ranking'!C24 -> 4 | D22: =B22 -> 4
A24: Booth pace before and after the big three sold out
A25: Period | B25: From | C25: To | D25: Clicker units | E25: Units per hour | F25: Sales
A26: Creeper, Dumpling or Avocado still on the table | B26: ='Design Ranking'!B7 -> 46312.418 | C26: =MAX('Design Ranking'!I14,'Design Ranking'!I12,'Design Ranking'!I15) -> 46312.53 | D26: =SUMIFS('Raw Data'!$F$2:$F$114,'Raw Data'!$D$2:$D$114,"Clickers & Fidget Toys",'Raw Data'!$C$2:$C$114,">="&B26,'Raw Data'!$C$2:$C$114,"<="&C26) -> 117 | E26: =D26/((C26-B26)*24) -> 43.386897 | F26: =COUNTIFS(Baskets!$C$2:$C$70,">="&B26,Baskets!$C$2:$C$70,"<="&C26) -> 65
A27: All three gone | B27: =C26 -> 46312.53 | C27: ='Design Ranking'!B8 -> 46312.556 | D27: =SUMIFS('Raw Data'!$F$2:$F$114,'Raw Data'!$D$2:$D$114,"Clickers & Fidget Toys",'Raw Data'!$C$2:$C$114,">"&B27,'Raw Data'!$C$2:$C$114,"<="&C27) -> 12 | E27: =D27/((C27-B27)*24) -> 19.485792 | F27: =COUNTIFS(Baskets!$C$2:$C$70,">"&B27,Baskets!$C$2:$C$70,"<="&C27) -> 4
A28: Some of the drop is the crowd thinning near the 1:00 PM close, so this shows the size of the slump, not how much of it stock caused.

Sheet Event Totals
A1: Event totals: tracked and estimated
A2: Blue cells are Sam's estimates from the Oct 17 chat. 1 ticket = $1.
A4: Tickets counted at the end | B4: 830
A5: Gross tickets (counted + helper food tickets) | B5: 900
A6: Clickers + copters, low (incl. blowout) | B6: 500
A7: Clickers + copters, high | B7: 530
A8: Balloon Battle, low | B8: 50
A9: Balloon Battle, high | B9: 60
A10: Plinko tickets per drop | B10: 1
A11: Balloon Battle tickets per match (per player) | B11: 5
A12: CCA's cut | B12: 0.1
A13: Dollars per ticket | B13: 1
A15: Booth | B15: Tracked tickets | C15: Estimate low | D15: Estimate high | E15: Best estimate | F15: Goal | G15: % of goal | H15: How we got it
A16: Clickers | B16: =SUMIFS('Raw Data'!$G$2:$G$114,'Raw Data'!$D$2:$D$114,"Clickers & Fidget Toys") -> 455 | C16: =B6-B17 -> 473 | D16: =B7-B17 -> 503 | E16: =AVERAGE(C16:D16) -> 488 | F16: 500 | G16: =E16/F16 -> 0.976 | H16: Sam's clickers + copters range minus tracked copters. Includes the untracked blowout.
A17: Copters | B17: =SUMIFS('Raw Data'!$G$2:$G$114,'Raw Data'!$D$2:$D$114,"Copters") -> 27 | C17: =B17 -> 27 | D17: =B17 -> 27 | E17: =AVERAGE(C17:D17) -> 27 | F17: 500 | G17: =E17/F17 -> 0.054 | H17: All tracked; none in the blowout.
A18: Balloon Battle | B18: 0 | C18: =B8 -> 50 | D18: =B9 -> 60 | E18: =AVERAGE(C18:D18) -> 55 | F18: 200 | G18: =E18/F18 -> 0.275 | H18: Sam's estimate; the Battle laptop wasn't exported.
A19: Plinko | B19: 0 | C19: =B5-B7-B9 -> 310 | D19: =B5-B6-B8 -> 350 | E19: =AVERAGE(C19:D19) -> 330 | F19: 100 | G19: =E19/F19 -> 3.3 | H19: Inferred: gross minus every other booth. Bucket wasn't counted.
A20: Total | B20: =SUM(B16:B19) -> 482 | C20: =SUM(C16:C19) -> 860 | D20: =SUM(D16:D19) -> 940 | E20: =SUM(E16:E19) -> 900 | F20: =SUM(F16:F19) -> 1300 | G20: =E20/F20 -> 0.69230769 | H20: Best-estimate total equals the gross by construction (Plinko is the remainder).
A22: Helper food tickets (gross minus counted) | B22: =B5-B4 -> 70
A23: Gross after CCA's 10% ($) | B23: =B5*(1-B12)*B13 -> 810
A24: Plinko drops (best estimate) | B24: =E19/B10 -> 330
A25: Balloon Battle player-matches, low | B25: =C18/B11 -> 10
A26: Balloon Battle player-matches, high | B26: =D18/B11 -> 12
A27: Free Pokemon cards given with purchases | B27: =SUM('Raw Data'!$K$2:$K$114) -> 24
A28: Tracked sales | B28: =COUNTA(Baskets!$A$2:$A$70) -> 69
A29: Average tickets per tracked sale | B29: =SUM(Baskets!$G$2:$G$70)/B28 -> 6.9855072

Sheet Themes
A1: Clicker themes
A2: Theme for each design is set on Design Ranking (column B). Sell-through only counts designs with a known starting count.
A4: Theme | B4: Designs | C4: Units sold | D4: Share of clicker units | E4: Tickets rung up | F4: Stock (known counts) | G4: Units (known counts) | H4: Sell-through
A5: Asian food | B5: Dumpling, Salmon nigiri, Egg tart, Spam musubi | C5: =SUMIFS('Raw Data'!$F$2:$F$114,'Raw Data'!$L$2:$L$114,A5) -> 64 | D5: =C5/SUM($C$5:$C$8) -> 0.49612403 | E5: =SUMIFS('Raw Data'!$G$2:$G$114,'Raw Data'!$L$2:$L$114,A5) -> 220 | F5: =SUMIFS('Design Ranking'!$C$12:$C$25,'Design Ranking'!$B$12:$B$25,A5,'Design Ranking'!$A$12:$A$25,"<>Oreo") -> 53 | G5: =SUMIFS('Design Ranking'!$E$12:$E$25,'Design Ranking'!$B$12:$B$25,A5,'Design Ranking'!$C$12:$C$25,"<>",'Design Ranking'!$A$12:$A$25,"<>Oreo") -> 53 | H5: =IF(F5=0,"",G5/F5) -> 1
A6: Snacks & treats | B6: Avocado, Chocolate bar, Hot dog bun, S'mores, Oreo, Burger | C6: =SUMIFS('Raw Data'!$F$2:$F$114,'Raw Data'!$L$2:$L$114,A6) -> 37 | D6: =C6/SUM($C$5:$C$8) -> 0.28682171 | E6: =SUMIFS('Raw Data'!$G$2:$G$114,'Raw Data'!$L$2:$L$114,A6) -> 135 | F6: =SUMIFS('Design Ranking'!$C$12:$C$25,'Design Ranking'!$B$12:$B$25,A6,'Design Ranking'!$A$12:$A$25,"<>Oreo") -> 58 | G6: =SUMIFS('Design Ranking'!$E$12:$E$25,'Design Ranking'!$B$12:$B$25,A6,'Design Ranking'!$C$12:$C$25,"<>",'Design Ranking'!$A$12:$A$25,"<>Oreo") -> 36 | H6: =IF(F6=0,"",G6/F6) -> 0.62068966
A7: Minecraft | B7: Creeper, Creeper infinity cube | C7: =SUMIFS('Raw Data'!$F$2:$F$114,'Raw Data'!$L$2:$L$114,A7) -> 18 | D7: =C7/SUM($C$5:$C$8) -> 0.13953488 | E7: =SUMIFS('Raw Data'!$G$2:$G$114,'Raw Data'!$L$2:$L$114,A7) -> 67 | F7: =SUMIFS('Design Ranking'!$C$12:$C$25,'Design Ranking'!$B$12:$B$25,A7,'Design Ranking'!$A$12:$A$25,"<>Oreo") -> 19 | G7: =SUMIFS('Design Ranking'!$E$12:$E$25,'Design Ranking'!$B$12:$B$25,A7,'Design Ranking'!$C$12:$C$25,"<>",'Design Ranking'!$A$12:$A$25,"<>Oreo") -> 18 | H7: =IF(F7=0,"",G7/F7) -> 0.94736842
A8: Workshop | B8: WD-40, LEGO brick | C8: =SUMIFS('Raw Data'!$F$2:$F$114,'Raw Data'!$L$2:$L$114,A8) -> 10 | D8: =C8/SUM($C$5:$C$8) -> 0.07751938 | E8: =SUMIFS('Raw Data'!$G$2:$G$114,'Raw Data'!$L$2:$L$114,A8) -> 33 | F8: =SUMIFS('Design Ranking'!$C$12:$C$25,'Design Ranking'!$B$12:$B$25,A8,'Design Ranking'!$A$12:$A$25,"<>Oreo") -> 19 | G8: =SUMIFS('Design Ranking'!$E$12:$E$25,'Design Ranking'!$B$12:$B$25,A8,'Design Ranking'!$C$12:$C$25,"<>",'Design Ranking'!$A$12:$A$25,"<>Oreo") -> 10 | H8: =IF(F8=0,"",G8/F8) -> 0.52631579
A9: Oreo is left out of stock and sell-through (not put out). Egg tart and Burger have no known count, so they count in units but not sell-through.
A12: How themes mixed in one sale
A13: Sale type | B13: Sales
A14: One design | B14: =COUNTIF(Baskets!$J$2:$J$70,1) -> 39
A15: Several designs, one theme | B15: =COUNTIFS(Baskets!$J$2:$J$70,">1",Baskets!$K$2:$K$70,1) -> 7
A16: Several designs, mixed themes | B16: =COUNTIFS(Baskets!$J$2:$J$70,">1",Baskets!$K$2:$K$70,">1") -> 23
A19: Sales containing both themes (diagonal: sales with that theme)
B20: Asian food | C20: Snacks & treats | D20: Minecraft | E20: Workshop | F20: Copters
A21: Asian food | B21: =SUMPRODUCT((Baskets!$L$2:$L$70>0)*(Baskets!$L$2:$L$70>0)) -> 38 | C21: =SUMPRODUCT((Baskets!$L$2:$L$70>0)*(Baskets!$M$2:$M$70>0)) -> 12 | D21: =SUMPRODUCT((Baskets!$L$2:$L$70>0)*(Baskets!$N$2:$N$70>0)) -> 5 | E21: =SUMPRODUCT((Baskets!$L$2:$L$70>0)*(Baskets!$O$2:$O$70>0)) -> 5 | F21: =SUMPRODUCT((Baskets!$L$2:$L$70>0)*(Baskets!$P$2:$P$70>0)) -> 0
A22: Snacks & treats | B22: =SUMPRODUCT((Baskets!$M$2:$M$70>0)*(Baskets!$L$2:$L$70>0)) -> 12 | C22: =SUMPRODUCT((Baskets!$M$2:$M$70>0)*(Baskets!$M$2:$M$70>0)) -> 30 | D22: =SUMPRODUCT((Baskets!$M$2:$M$70>0)*(Baskets!$N$2:$N$70>0)) -> 5 | E22: =SUMPRODUCT((Baskets!$M$2:$M$70>0)*(Baskets!$O$2:$O$70>0)) -> 5 | F22: =SUMPRODUCT((Baskets!$M$2:$M$70>0)*(Baskets!$P$2:$P$70>0)) -> 0
A23: Minecraft | B23: =SUMPRODUCT((Baskets!$N$2:$N$70>0)*(Baskets!$L$2:$L$70>0)) -> 5 | C23: =SUMPRODUCT((Baskets!$N$2:$N$70>0)*(Baskets!$M$2:$M$70>0)) -> 5 | D23: =SUMPRODUCT((Baskets!$N$2:$N$70>0)*(Baskets!$N$2:$N$70>0)) -> 15 | E23: =SUMPRODUCT((Baskets!$N$2:$N$70>0)*(Baskets!$O$2:$O$70>0)) -> 1 | F23: =SUMPRODUCT((Baskets!$N$2:$N$70>0)*(Baskets!$P$2:$P$70>0)) -> 0
A24: Workshop | B24: =SUMPRODUCT((Baskets!$O$2:$O$70>0)*(Baskets!$L$2:$L$70>0)) -> 5 | C24: =SUMPRODUCT((Baskets!$O$2:$O$70>0)*(Baskets!$M$2:$M$70>0)) -> 5 | D24: =SUMPRODUCT((Baskets!$O$2:$O$70>0)*(Baskets!$N$2:$N$70>0)) -> 1 | E24: =SUMPRODUCT((Baskets!$O$2:$O$70>0)*(Baskets!$O$2:$O$70>0)) -> 9 | F24: =SUMPRODUCT((Baskets!$O$2:$O$70>0)*(Baskets!$P$2:$P$70>0)) -> 0
A25: Copters | B25: =SUMPRODUCT((Baskets!$P$2:$P$70>0)*(Baskets!$L$2:$L$70>0)) -> 0 | C25: =SUMPRODUCT((Baskets!$P$2:$P$70>0)*(Baskets!$M$2:$M$70>0)) -> 0 | D25: =SUMPRODUCT((Baskets!$P$2:$P$70>0)*(Baskets!$N$2:$N$70>0)) -> 0 | E25: =SUMPRODUCT((Baskets!$P$2:$P$70>0)*(Baskets!$O$2:$O$70>0)) -> 0 | F25: =SUMPRODUCT((Baskets!$P$2:$P$70>0)*(Baskets!$P$2:$P$70>0)) -> 5

Sheet Pairings
A1: Designs bought together
A2: Each cell counts sales that had both designs. The diagonal counts sales with that design at all.
A4: Top pairs
A5: Design A | B5: Design B | C5: Sales together
A6: Avocado | B6: Dumpling | C6: =SUMPRODUCT((Baskets!$U$2:$U$70>0)*(Baskets!$V$2:$V$70>0)) -> 4
A7: Creeper | B7: Dumpling | C7: =SUMPRODUCT((Baskets!$W$2:$W$70>0)*(Baskets!$V$2:$V$70>0)) -> 3
A8: Avocado | B8: Egg tart | C8: =SUMPRODUCT((Baskets!$U$2:$U$70>0)*(Baskets!$Q$2:$Q$70>0)) -> 3
A9: Dumpling | B9: Egg tart | C9: =SUMPRODUCT((Baskets!$V$2:$V$70>0)*(Baskets!$Q$2:$Q$70>0)) -> 3
A10: Dumpling | B10: Spam musubi | C10: =SUMPRODUCT((Baskets!$V$2:$V$70>0)*(Baskets!$Y$2:$Y$70>0)) -> 2
A11: Dumpling | B11: WD-40 | C11: =SUMPRODUCT((Baskets!$V$2:$V$70>0)*(Baskets!$AB$2:$AB$70>0)) -> 2
A12: Chocolate bar | B12: Creeper | C12: =SUMPRODUCT((Baskets!$T$2:$T$70>0)*(Baskets!$W$2:$W$70>0)) -> 2
A13: Chocolate bar | B13: Salmon nigiri | C13: =SUMPRODUCT((Baskets!$T$2:$T$70>0)*(Baskets!$Z$2:$Z$70>0)) -> 2
A14: Salmon nigiri | B14: Spam musubi | C14: =SUMPRODUCT((Baskets!$Z$2:$Z$70>0)*(Baskets!$Y$2:$Y$70>0)) -> 2
A15: Hot dog bun | B15: WD-40 | C15: =SUMPRODUCT((Baskets!$R$2:$R$70>0)*(Baskets!$AB$2:$AB$70>0)) -> 2
A16: Avocado | B16: Salmon nigiri | C16: =SUMPRODUCT((Baskets!$U$2:$U$70>0)*(Baskets!$Z$2:$Z$70>0)) -> 2
A17: LEGO brick | B17: Salmon nigiri | C17: =SUMPRODUCT((Baskets!$AA$2:$AA$70>0)*(Baskets!$Z$2:$Z$70>0)) -> 2
A18: Creeper | B18: Hot dog bun | C18: =SUMPRODUCT((Baskets!$W$2:$W$70>0)*(Baskets!$R$2:$R$70>0)) -> 2
A19: Dumpling | B19: Hot dog bun | C19: =SUMPRODUCT((Baskets!$V$2:$V$70>0)*(Baskets!$R$2:$R$70>0)) -> 2
A20: Chocolate bar | B20: Hot dog bun | C20: =SUMPRODUCT((Baskets!$T$2:$T$70>0)*(Baskets!$R$2:$R$70>0)) -> 2
A21: Dumpling | B21: Salmon nigiri | C21: =SUMPRODUCT((Baskets!$V$2:$V$70>0)*(Baskets!$Z$2:$Z$70>0)) -> 2
A22: Avocado | B22: Hot dog bun | C22: =SUMPRODUCT((Baskets!$U$2:$U$70>0)*(Baskets!$R$2:$R$70>0)) -> 2
A23: Egg tart | B23: Salmon nigiri | C23: =SUMPRODUCT((Baskets!$Q$2:$Q$70>0)*(Baskets!$Z$2:$Z$70>0)) -> 2
A25: Pairs that happened once are in the matrix below.
A27: Pair matrix
B28: Dumpling | C28: Salmon nigiri | D28: Creeper | E28: Avocado | F28: Egg tart | G28: Chocolate bar | H28: Hot dog bun | I28: WD-40 | J28: Creeper infinity cube | K28: Spam musubi | L28: S'mores | M28: LEGO brick | N28: Burger | O28: Full kit | P28: Kit w/ toroidal
A29: Dumpling | B29: =SUMPRODUCT((Baskets!$V$2:$V$70>0)*(Baskets!$V$2:$V$70>0)) -> 16 | C29: =SUMPRODUCT((Baskets!$V$2:$V$70>0)*(Baskets!$Z$2:$Z$70>0)) -> 2 | D29: =SUMPRODUCT((Baskets!$V$2:$V$70>0)*(Baskets!$W$2:$W$70>0)) -> 3 | E29: =SUMPRODUCT((Baskets!$V$2:$V$70>0)*(Baskets!$U$2:$U$70>0)) -> 4 | F29: =SUMPRODUCT((Baskets!$V$2:$V$70>0)*(Baskets!$Q$2:$Q$70>0)) -> 3 | G29: =SUMPRODUCT((Baskets!$V$2:$V$70>0)*(Baskets!$T$2:$T$70>0)) -> 0 | H29: =SUMPRODUCT((Baskets!$V$2:$V$70>0)*(Baskets!$R$2:$R$70>0)) -> 2 | I29: =SUMPRODUCT((Baskets!$V$2:$V$70>0)*(Baskets!$AB$2:$AB$70>0)) -> 2 | J29: =SUMPRODUCT((Baskets!$V$2:$V$70>0)*(Baskets!$AC$2:$AC$70>0)) -> 1 | K29: =SUMPRODUCT((Baskets!$V$2:$V$70>0)*(Baskets!$Y$2:$Y$70>0)) -> 2 | L29: =SUMPRODUCT((Baskets!$V$2:$V$70>0)*(Baskets!$S$2:$S$70>0)) -> 0 | M29: =SUMPRODUCT((Baskets!$V$2:$V$70>0)*(Baskets!$AA$2:$AA$70>0)) -> 0 | N29: =SUMPRODUCT((Baskets!$V$2:$V$70>0)*(Baskets!$AD$2:$AD$70>0)) -> 0 | O29: =SUMPRODUCT((Baskets!$V$2:$V$70>0)*(Baskets!$AE$2:$AE$70>0)) -> 0 | P29: =SUMPRODUCT((Baskets!$V$2:$V$70>0)*(Baskets!$AF$2:$AF$70>0)) -> 0
A30: Salmon nigiri | B30: =SUMPRODUCT((Baskets!$Z$2:$Z$70>0)*(Baskets!$V$2:$V$70>0)) -> 2 | C30: =SUMPRODUCT((Baskets!$Z$2:$Z$70>0)*(Baskets!$Z$2:$Z$70>0)) -> 18 | D30: =SUMPRODUCT((Baskets!$Z$2:$Z$70>0)*(Baskets!$W$2:$W$70>0)) -> 1 | E30: =SUMPRODUCT((Baskets!$Z$2:$Z$70>0)*(Baskets!$U$2:$U$70>0)) -> 2 | F30: =SUMPRODUCT((Baskets!$Z$2:$Z$70>0)*(Baskets!$Q$2:$Q$70>0)) -> 2 | G30: =SUMPRODUCT((Baskets!$Z$2:$Z$70>0)*(Baskets!$T$2:$T$70>0)) -> 2 | H30: =SUMPRODUCT((Baskets!$Z$2:$Z$70>0)*(Baskets!$R$2:$R$70>0)) -> 0 | I30: =SUMPRODUCT((Baskets!$Z$2:$Z$70>0)*(Baskets!$AB$2:$AB$70>0)) -> 0 | J30: =SUMPRODUCT((Baskets!$Z$2:$Z$70>0)*(Baskets!$AC$2:$AC$70>0)) -> 1 | K30: =SUMPRODUCT((Baskets!$Z$2:$Z$70>0)*(Baskets!$Y$2:$Y$70>0)) -> 2 | L30: =SUMPRODUCT((Baskets!$Z$2:$Z$70>0)*(Baskets!$S$2:$S$70>0)) -> 1 | M30: =SUMPRODUCT((Baskets!$Z$2:$Z$70>0)*(Baskets!$AA$2:$AA$70>0)) -> 2 | N30: =SUMPRODUCT((Baskets!$Z$2:$Z$70>0)*(Baskets!$AD$2:$AD$70>0)) -> 1 | O30: =SUMPRODUCT((Baskets!$Z$2:$Z$70>0)*(Baskets!$AE$2:$AE$70>0)) -> 0 | P30: =SUMPRODUCT((Baskets!$Z$2:$Z$70>0)*(Baskets!$AF$2:$AF$70>0)) -> 0
A31: Creeper | B31: =SUMPRODUCT((Baskets!$W$2:$W$70>0)*(Baskets!$V$2:$V$70>0)) -> 3 | C31: =SUMPRODUCT((Baskets!$W$2:$W$70>0)*(Baskets!$Z$2:$Z$70>0)) -> 1 | D31: =SUMPRODUCT((Baskets!$W$2:$W$70>0)*(Baskets!$W$2:$W$70>0)) -> 10 | E31: =SUMPRODUCT((Baskets!$W$2:$W$70>0)*(Baskets!$U$2:$U$70>0)) -> 0 | F31: =SUMPRODUCT((Baskets!$W$2:$W$70>0)*(Baskets!$Q$2:$Q$70>0)) -> 0 | G31: =SUMPRODUCT((Baskets!$W$2:$W$70>0)*(Baskets!$T$2:$T$70>0)) -> 2 | H31: =SUMPRODUCT((Baskets!$W$2:$W$70>0)*(Baskets!$R$2:$R$70>0)) -> 2 | I31: =SUMPRODUCT((Baskets!$W$2:$W$70>0)*(Baskets!$AB$2:$AB$70>0)) -> 0 | J31: =SUMPRODUCT((Baskets!$W$2:$W$70>0)*(Baskets!$AC$2:$AC$70>0)) -> 1 | K31: =SUMPRODUCT((Baskets!$W$2:$W$70>0)*(Baskets!$Y$2:$Y$70>0)) -> 0 | L31: =SUMPRODUCT((Baskets!$W$2:$W$70>0)*(Baskets!$S$2:$S$70>0)) -> 0 | M31: =SUMPRODUCT((Baskets!$W$2:$W$70>0)*(Baskets!$AA$2:$AA$70>0)) -> 0 | N31: =SUMPRODUCT((Baskets!$W$2:$W$70>0)*(Baskets!$AD$2:$AD$70>0)) -> 0 | O31: =SUMPRODUCT((Baskets!$W$2:$W$70>0)*(Baskets!$AE$2:$AE$70>0)) -> 0 | P31: =SUMPRODUCT((Baskets!$W$2:$W$70>0)*(Baskets!$AF$2:$AF$70>0)) -> 0
A32: Avocado | B32: =SUMPRODUCT((Baskets!$U$2:$U$70>0)*(Baskets!$V$2:$V$70>0)) -> 4 | C32: =SUMPRODUCT((Baskets!$U$2:$U$70>0)*(Baskets!$Z$2:$Z$70>0)) -> 2 | D32: =SUMPRODUCT((Baskets!$U$2:$U$70>0)*(Baskets!$W$2:$W$70>0)) -> 0 | E32: =SUMPRODUCT((Baskets!$U$2:$U$70>0)*(Baskets!$U$2:$U$70>0)) -> 10 | F32: =SUMPRODUCT((Baskets!$U$2:$U$70>0)*(Baskets!$Q$2:$Q$70>0)) -> 3 | G32: =SUMPRODUCT((Baskets!$U$2:$U$70>0)*(Baskets!$T$2:$T$70>0)) -> 0 | H32: =SUMPRODUCT((Baskets!$U$2:$U$70>0)*(Baskets!$R$2:$R$70>0)) -> 2 | I32: =SUMPRODUCT((Baskets!$U$2:$U$70>0)*(Baskets!$AB$2:$AB$70>0)) -> 0 | J32: =SUMPRODUCT((Baskets!$U$2:$U$70>0)*(Baskets!$AC$2:$AC$70>0)) -> 1 | K32: =SUMPRODUCT((Baskets!$U$2:$U$70>0)*(Baskets!$Y$2:$Y$70>0)) -> 1 | L32: =SUMPRODUCT((Baskets!$U$2:$U$70>0)*(Baskets!$S$2:$S$70>0)) -> 0 | M32: =SUMPRODUCT((Baskets!$U$2:$U$70>0)*(Baskets!$AA$2:$AA$70>0)) -> 1 | N32: =SUMPRODUCT((Baskets!$U$2:$U$70>0)*(Baskets!$AD$2:$AD$70>0)) -> 0 | O32: =SUMPRODUCT((Baskets!$U$2:$U$70>0)*(Baskets!$AE$2:$AE$70>0)) -> 0 | P32: =SUMPRODUCT((Baskets!$U$2:$U$70>0)*(Baskets!$AF$2:$AF$70>0)) -> 0
A33: Egg tart | B33: =SUMPRODUCT((Baskets!$Q$2:$Q$70>0)*(Baskets!$V$2:$V$70>0)) -> 3 | C33: =SUMPRODUCT((Baskets!$Q$2:$Q$70>0)*(Baskets!$Z$2:$Z$70>0)) -> 2 | D33: =SUMPRODUCT((Baskets!$Q$2:$Q$70>0)*(Baskets!$W$2:$W$70>0)) -> 0 | E33: =SUMPRODUCT((Baskets!$Q$2:$Q$70>0)*(Baskets!$U$2:$U$70>0)) -> 3 | F33: =SUMPRODUCT((Baskets!$Q$2:$Q$70>0)*(Baskets!$Q$2:$Q$70>0)) -> 10 | G33: =SUMPRODUCT((Baskets!$Q$2:$Q$70>0)*(Baskets!$T$2:$T$70>0)) -> 0 | H33: =SUMPRODUCT((Baskets!$Q$2:$Q$70>0)*(Baskets!$R$2:$R$70>0)) -> 0 | I33: =SUMPRODUCT((Baskets!$Q$2:$Q$70>0)*(Baskets!$AB$2:$AB$70>0)) -> 1 | J33: =SUMPRODUCT((Baskets!$Q$2:$Q$70>0)*(Baskets!$AC$2:$AC$70>0)) -> 0 | K33: =SUMPRODUCT((Baskets!$Q$2:$Q$70>0)*(Baskets!$Y$2:$Y$70>0)) -> 1 | L33: =SUMPRODUCT((Baskets!$Q$2:$Q$70>0)*(Baskets!$S$2:$S$70>0)) -> 0 | M33: =SUMPRODUCT((Baskets!$Q$2:$Q$70>0)*(Baskets!$AA$2:$AA$70>0)) -> 0 | N33: =SUMPRODUCT((Baskets!$Q$2:$Q$70>0)*(Baskets!$AD$2:$AD$70>0)) -> 0 | O33: =SUMPRODUCT((Baskets!$Q$2:$Q$70>0)*(Baskets!$AE$2:$AE$70>0)) -> 0 | P33: =SUMPRODUCT((Baskets!$Q$2:$Q$70>0)*(Baskets!$AF$2:$AF$70>0)) -> 0
A34: Chocolate bar | B34: =SUMPRODUCT((Baskets!$T$2:$T$70>0)*(Baskets!$V$2:$V$70>0)) -> 0 | C34: =SUMPRODUCT((Baskets!$T$2:$T$70>0)*(Baskets!$Z$2:$Z$70>0)) -> 2 | D34: =SUMPRODUCT((Baskets!$T$2:$T$70>0)*(Baskets!$W$2:$W$70>0)) -> 2 | E34: =SUMPRODUCT((Baskets!$T$2:$T$70>0)*(Baskets!$U$2:$U$70>0)) -> 0 | F34: =SUMPRODUCT((Baskets!$T$2:$T$70>0)*(Baskets!$Q$2:$Q$70>0)) -> 0 | G34: =SUMPRODUCT((Baskets!$T$2:$T$70>0)*(Baskets!$T$2:$T$70>0)) -> 11 | H34: =SUMPRODUCT((Baskets!$T$2:$T$70>0)*(Baskets!$R$2:$R$70>0)) -> 2 | I34: =SUMPRODUCT((Baskets!$T$2:$T$70>0)*(Baskets!$AB$2:$AB$70>0)) -> 1 | J34: =SUMPRODUCT((Baskets!$T$2:$T$70>0)*(Baskets!$AC$2:$AC$70>0)) -> 1 | K34: =SUMPRODUCT((Baskets!$T$2:$T$70>0)*(Baskets!$Y$2:$Y$70>0)) -> 0 | L34: =SUMPRODUCT((Baskets!$T$2:$T$70>0)*(Baskets!$S$2:$S$70>0)) -> 0 | M34: =SUMPRODUCT((Baskets!$T$2:$T$70>0)*(Baskets!$AA$2:$AA$70>0)) -> 1 | N34: =SUMPRODUCT((Baskets!$T$2:$T$70>0)*(Baskets!$AD$2:$AD$70>0)) -> 0 | O34: =SUMPRODUCT((Baskets!$T$2:$T$70>0)*(Baskets!$AE$2:$AE$70>0)) -> 0 | P34: =SUMPRODUCT((Baskets!$T$2:$T$70>0)*(Baskets!$AF$2:$AF$70>0)) -> 0
A35: Hot dog bun | B35: =SUMPRODUCT((Baskets!$R$2:$R$70>0)*(Baskets!$V$2:$V$70>0)) -> 2 | C35: =SUMPRODUCT((Baskets!$R$2:$R$70>0)*(Baskets!$Z$2:$Z$70>0)) -> 0 | D35: =SUMPRODUCT((Baskets!$R$2:$R$70>0)*(Baskets!$W$2:$W$70>0)) -> 2 | E35: =SUMPRODUCT((Baskets!$R$2:$R$70>0)*(Baskets!$U$2:$U$70>0)) -> 2 | F35: =SUMPRODUCT((Baskets!$R$2:$R$70>0)*(Baskets!$Q$2:$Q$70>0)) -> 0 | G35: =SUMPRODUCT((Baskets!$R$2:$R$70>0)*(Baskets!$T$2:$T$70>0)) -> 2 | H35: =SUMPRODUCT((Baskets!$R$2:$R$70>0)*(Baskets!$R$2:$R$70>0)) -> 10 | I35: =SUMPRODUCT((Baskets!$R$2:$R$70>0)*(Baskets!$AB$2:$AB$70>0)) -> 2 | J35: =SUMPRODUCT((Baskets!$R$2:$R$70>0)*(Baskets!$AC$2:$AC$70>0)) -> 0 | K35: =SUMPRODUCT((Baskets!$R$2:$R$70>0)*(Baskets!$Y$2:$Y$70>0)) -> 1 | L35: =SUMPRODUCT((Baskets!$R$2:$R$70>0)*(Baskets!$S$2:$S$70>0)) -> 0 | M35: =SUMPRODUCT((Baskets!$R$2:$R$70>0)*(Baskets!$AA$2:$AA$70>0)) -> 0 | N35: =SUMPRODUCT((Baskets!$R$2:$R$70>0)*(Baskets!$AD$2:$AD$70>0)) -> 0 | O35: =SUMPRODUCT((Baskets!$R$2:$R$70>0)*(Baskets!$AE$2:$AE$70>0)) -> 0 | P35: =SUMPRODUCT((Baskets!$R$2:$R$70>0)*(Baskets!$AF$2:$AF$70>0)) -> 0
A36: WD-40 | B36: =SUMPRODUCT((Baskets!$AB$2:$AB$70>0)*(Baskets!$V$2:$V$70>0)) -> 2 | C36: =SUMPRODUCT((Baskets!$AB$2:$AB$70>0)*(Baskets!$Z$2:$Z$70>0)) -> 0 | D36: =SUMPRODUCT((Baskets!$AB$2:$AB$70>0)*(Baskets!$W$2:$W$70>0)) -> 0 | E36: =SUMPRODUCT((Baskets!$AB$2:$AB$70>0)*(Baskets!$U$2:$U$70>0)) -> 0 | F36: =SUMPRODUCT((Baskets!$AB$2:$AB$70>0)*(Baskets!$Q$2:$Q$70>0)) -> 1 | G36: =SUMPRODUCT((Baskets!$AB$2:$AB$70>0)*(Baskets!$T$2:$T$70>0)) -> 1 | H36: =SUMPRODUCT((Baskets!$AB$2:$AB$70>0)*(Baskets!$R$2:$R$70>0)) -> 2 | I36: =SUMPRODUCT((Baskets!$AB$2:$AB$70>0)*(Baskets!$AB$2:$AB$70>0)) -> 7 | J36: =SUMPRODUCT((Baskets!$AB$2:$AB$70>0)*(Baskets!$AC$2:$AC$70>0)) -> 1 | K36: =SUMPRODUCT((Baskets!$AB$2:$AB$70>0)*(Baskets!$Y$2:$Y$70>0)) -> 1 | L36: =SUMPRODUCT((Baskets!$AB$2:$AB$70>0)*(Baskets!$S$2:$S$70>0)) -> 0 | M36: =SUMPRODUCT((Baskets!$AB$2:$AB$70>0)*(Baskets!$AA$2:$AA$70>0)) -> 0 | N36: =SUMPRODUCT((Baskets!$AB$2:$AB$70>0)*(Baskets!$AD$2:$AD$70>0)) -> 0 | O36: =SUMPRODUCT((Baskets!$AB$2:$AB$70>0)*(Baskets!$AE$2:$AE$70>0)) -> 0 | P36: =SUMPRODUCT((Baskets!$AB$2:$AB$70>0)*(Baskets!$AF$2:$AF$70>0)) -> 0
A37: Creeper infinity cube | B37: =SUMPRODUCT((Baskets!$AC$2:$AC$70>0)*(Baskets!$V$2:$V$70>0)) -> 1 | C37: =SUMPRODUCT((Baskets!$AC$2:$AC$70>0)*(Baskets!$Z$2:$Z$70>0)) -> 1 | D37: =SUMPRODUCT((Baskets!$AC$2:$AC$70>0)*(Baskets!$W$2:$W$70>0)) -> 1 | E37: =SUMPRODUCT((Baskets!$AC$2:$AC$70>0)*(Baskets!$U$2:$U$70>0)) -> 1 | F37: =SUMPRODUCT((Baskets!$AC$2:$AC$70>0)*(Baskets!$Q$2:$Q$70>0)) -> 0 | G37: =SUMPRODUCT((Baskets!$AC$2:$AC$70>0)*(Baskets!$T$2:$T$70>0)) -> 1 | H37: =SUMPRODUCT((Baskets!$AC$2:$AC$70>0)*(Baskets!$R$2:$R$70>0)) -> 0 | I37: =SUMPRODUCT((Baskets!$AC$2:$AC$70>0)*(Baskets!$AB$2:$AB$70>0)) -> 1 | J37: =SUMPRODUCT((Baskets!$AC$2:$AC$70>0)*(Baskets!$AC$2:$AC$70>0)) -> 6 | K37: =SUMPRODUCT((Baskets!$AC$2:$AC$70>0)*(Baskets!$Y$2:$Y$70>0)) -> 0 | L37: =SUMPRODUCT((Baskets!$AC$2:$AC$70>0)*(Baskets!$S$2:$S$70>0)) -> 0 | M37: =SUMPRODUCT((Baskets!$AC$2:$AC$70>0)*(Baskets!$AA$2:$AA$70>0)) -> 0 | N37: =SUMPRODUCT((Baskets!$AC$2:$AC$70>0)*(Baskets!$AD$2:$AD$70>0)) -> 0 | O37: =SUMPRODUCT((Baskets!$AC$2:$AC$70>0)*(Baskets!$AE$2:$AE$70>0)) -> 0 | P37: =SUMPRODUCT((Baskets!$AC$2:$AC$70>0)*(Baskets!$AF$2:$AF$70>0)) -> 0
A38: Spam musubi | B38: =SUMPRODUCT((Baskets!$Y$2:$Y$70>0)*(Baskets!$V$2:$V$70>0)) -> 2 | C38: =SUMPRODUCT((Baskets!$Y$2:$Y$70>0)*(Baskets!$Z$2:$Z$70>0)) -> 2 | D38: =SUMPRODUCT((Baskets!$Y$2:$Y$70>0)*(Baskets!$W$2:$W$70>0)) -> 0 | E38: =SUMPRODUCT((Baskets!$Y$2:$Y$70>0)*(Baskets!$U$2:$U$70>0)) -> 1 | F38: =SUMPRODUCT((Baskets!$Y$2:$Y$70>0)*(Baskets!$Q$2:$Q$70>0)) -> 1 | G38: =SUMPRODUCT((Baskets!$Y$2:$Y$70>0)*(Baskets!$T$2:$T$70>0)) -> 0 | H38: =SUMPRODUCT((Baskets!$Y$2:$Y$70>0)*(Baskets!$R$2:$R$70>0)) -> 1 | I38: =SUMPRODUCT((Baskets!$Y$2:$Y$70>0)*(Baskets!$AB$2:$AB$70>0)) -> 1 | J38: =SUMPRODUCT((Baskets!$Y$2:$Y$70>0)*(Baskets!$AC$2:$AC$70>0)) -> 0 | K38: =SUMPRODUCT((Baskets!$Y$2:$Y$70>0)*(Baskets!$Y$2:$Y$70>0)) -> 5 | L38: =SUMPRODUCT((Baskets!$Y$2:$Y$70>0)*(Baskets!$S$2:$S$70>0)) -> 0 | M38: =SUMPRODUCT((Baskets!$Y$2:$Y$70>0)*(Baskets!$AA$2:$AA$70>0)) -> 0 | N38: =SUMPRODUCT((Baskets!$Y$2:$Y$70>0)*(Baskets!$AD$2:$AD$70>0)) -> 0 | O38: =SUMPRODUCT((Baskets!$Y$2:$Y$70>0)*(Baskets!$AE$2:$AE$70>0)) -> 0 | P38: =SUMPRODUCT((Baskets!$Y$2:$Y$70>0)*(Baskets!$AF$2:$AF$70>0)) -> 0
A39: S'mores | B39: =SUMPRODUCT((Baskets!$S$2:$S$70>0)*(Baskets!$V$2:$V$70>0)) -> 0 | C39: =SUMPRODUCT((Baskets!$S$2:$S$70>0)*(Baskets!$Z$2:$Z$70>0)) -> 1 | D39: =SUMPRODUCT((Baskets!$S$2:$S$70>0)*(Baskets!$W$2:$W$70>0)) -> 0 | E39: =SUMPRODUCT((Baskets!$S$2:$S$70>0)*(Baskets!$U$2:$U$70>0)) -> 0 | F39: =SUMPRODUCT((Baskets!$S$2:$S$70>0)*(Baskets!$Q$2:$Q$70>0)) -> 0 | G39: =SUMPRODUCT((Baskets!$S$2:$S$70>0)*(Baskets!$T$2:$T$70>0)) -> 0 | H39: =SUMPRODUCT((Baskets!$S$2:$S$70>0)*(Baskets!$R$2:$R$70>0)) -> 0 | I39: =SUMPRODUCT((Baskets!$S$2:$S$70>0)*(Baskets!$AB$2:$AB$70>0)) -> 0 | J39: =SUMPRODUCT((Baskets!$S$2:$S$70>0)*(Baskets!$AC$2:$AC$70>0)) -> 0 | K39: =SUMPRODUCT((Baskets!$S$2:$S$70>0)*(Baskets!$Y$2:$Y$70>0)) -> 0 | L39: =SUMPRODUCT((Baskets!$S$2:$S$70>0)*(Baskets!$S$2:$S$70>0)) -> 2 | M39: =SUMPRODUCT((Baskets!$S$2:$S$70>0)*(Baskets!$AA$2:$AA$70>0)) -> 0 | N39: =SUMPRODUCT((Baskets!$S$2:$S$70>0)*(Baskets!$AD$2:$AD$70>0)) -> 0 | O39: =SUMPRODUCT((Baskets!$S$2:$S$70>0)*(Baskets!$AE$2:$AE$70>0)) -> 0 | P39: =SUMPRODUCT((Baskets!$S$2:$S$70>0)*(Baskets!$AF$2:$AF$70>0)) -> 0
